Workbook
Name NativeTimeline_Order_Date: #N/A

Sheet customer_data
B1: Customer ID | C1: Customer Name | D1: Email | E1: Phone Number | F1: Address Line 1 | G1: City | H1: Country | I1: Postcode | J1: Loyalty Card
B2: 17670-51384-MA | C2: Aloisia Allner | D2: aallner0@lulu.com | E2: +1 (862) 817-0124 | F2: 57999 Pepper Wood Alley | G2: =_xlfn.XLOOKUP(C2,customer_data!$B$1:$B$165,customer_data!D1) -> #VALUE! | H2: United States | I2: 7505 | J2: Yes
B3: 73342-18763-UW | C3: Piotr Bote | D3: pbote1@yelp.com | E3: +353 (913) 396-4653 | F3: 2112 Ridgeway Hill | G3: Crumlin | H3: Ireland | I3: D6W | J3: No
B4: 21125-22134-PX | C4: Jami Redholes | D4: jredholes2@tmall.com | E4: +1 (210) 986-6806 | F4: 5214 Bartillon Park | G4: San Antonio | H4: United States | I4: 78205 | J4: Yes
B5: 71253-00052-RN | C5: Dene Azema | D5: dazema3@facebook.com | E5: +1 (217) 418-0714 | F5: 27 Maywood Place | G5: Springfield | H5: United States | I5: 62711 | J5: Yes
B6: 23806-46781-OU | C6: Christoffer O' Shea | E6: +353 (698) 362-9201 | F6: 38980 Manitowish Junction | G6: Cill Airne | H6: Ireland | I6: N41 | J6: No
B7: 86561-91660-RB | C7: Beryle Cottier | E7: +1 (570) 289-7473 | F7: 2651 Stoughton Place | G7: Scranton | H7: United States | I7: 18505 | J7: No
B8: 65223-29612-CB | C8: Shaylynn Lobe | D8: slobe6@nifty.com | E8: +1 (937) 954-4541 | F8: 7005 Mariners Cove Place | G8: Dayton | H8: United States | I8: 45440 | J8: Yes
B9: 21134-81676-FR | C9: Melvin Wharfe | E9: +353 (507) 574-3034 | F9: 7 Straubel Road | G9: Kill | H9: Ireland | I9: P24 | J9: Yes
B10: 03396-68805-ZC | C10: Guthrey Petracci | D10: gpetracci8@livejournal.com | E10: +1 (310) 868-1842 | F10: 949 Paget Parkway | G10: Los Angeles | H10: United States | I10: 90045 | J10: No
B11: 61021-27840-ZN | C11: Rodger Raven | D11: rraven9@ed.gov | E11: +1 (213) 263-0288 | F11: 1 Reinke Avenue | G11: Los Angeles | H11: United States | I11: 90065 | J11: No
B12: 76239-90137-UQ | C12: Ferrell Ferber | D12: fferbera@businesswire.com | E12: +1 (408) 383-5302 | F12: 68 High Crossing Court | G12: San Jose | H12: United States | I12: 95160 | J12: No
B13: 49315-21985-BB | C13: Duky Phizackerly | D13: dphizackerlyb@utexas.edu | E13: +1 (408) 533-6012 | F13: 28643 Bluejay Crossing | G13: San Jose | H13: United States | I13: 95194 | J13: Yes
B14: 34136-36674-OM | C14: Rosaleen Scholar | D14: rscholarc@nyu.edu | E14: +1 (804) 420-0420 | F14: 80915 Montana Park | G14: Richmond | H14: United States | I14: 23285 | J14: No
B15: 39396-12890-PE | C15: Terence Vanyutin | D15: tvanyutind@wix.com | F15: 331 Bunting Hill | G15: Migrate | H15: United States | I15: 41905 | J15: No
B16: 95875-73336-RG | C16: Patrice Trobe | D16: ptrobee@wunderground.com | E16: +1 (314) 240-7896 | F16: 827 Declaration Plaza | G16: Saint Louis | H16: United States | I16: 63131 | J16: Yes
B17: 25473-43727-BY | C17: Llywellyn Oscroft | D17: loscroftf@ebay.co.uk | F17: 022 Roth Place | G17: Philadelphia | H17: United States | I17: 19172 | J17: No
B18: 99643-51048-IQ | C18: Minni Alabaster | D18: malabasterg@hexun.com | E18: +1 (971) 483-6255 | F18: 3 Charing Cross Trail | G18: Portland | H18: United States | I18: 97271 | J18: No
B19: 62173-15287-CU | C19: Rhianon Broxup | D19: rbroxuph@jimdo.com | E19: +1 (713) 663-1338 | F19: 83517 Thierer Court | G19: Houston | H19: United States | I19: 77240 | J19: No
B20: 57611-05522-ST | C20: Pall Redford | D20: predfordi@ow.ly | F20: 7337 Hayes Junction | G20: Caherconlish | H20: Ireland | I20: F45 | J20: Yes
B21: 76664-37050-DT | C21: Aurea Corradino | D21: acorradinoj@harvard.edu | E21: +1 (646) 202-5965 | F21: 698 Canary Terrace | G21: New York City | H21: United States | I21: 10060 | J21: Yes
B22: 84565-53984-SX | C22: Kendal Scardefield | E22: +353 (733) 405-3302 | F22: 3 Northridge Crossing | G22: Clondalkin | H22: Ireland | I22: D24 | J22: Yes
B23: 03090-88267-BQ | C23: Avrit Davidowsky | D23: adavidowskyl@netvibes.com | E23: +1 (616) 481-9962 | F23: 9 Warrior Junction | G23: Grand Rapids | H23: United States | I23: 49560 | J23: No
B24: 37651-47492-NC | C24: Annabel Antuk | D24: aantukm@kickstarter.com | E24: +1 (941) 740-6268 | F24: 77965 Lawn Park | G24: Punta Gorda | H24: United States | I24: 33982 | J24: Yes
B25: 95399-57205-HI | C25: Iorgo Kleinert | D25: ikleinertn@timesonline.co.uk | E25: +1 (360) 352-6598 | F25: 1 Morningstar Lane | G25: Vancouver | H25: United States | I25: 98682 | J25: Yes
B26: 24010-66714-HW | C26: Chrisy Blofeld | D26: cblofeldo@amazon.co.uk | E26: +1 (303) 936-3357 | F26: 013 Talisman Terrace | G26: Englewood | H26: United States | I26: 80150 | J26: No
B27: 07591-92789-UA | C27: Culley Farris | E27: +1 (941) 267-4822 | F27: 4 Mitchell Drive | G27: Punta Gorda | H27: United States | I27: 33982 | J27: Yes
B28: 49231-44455-IC | C28: Selene Shales | D28: sshalesq@umich.edu | E28: +1 (707) 881-5004 | F28: 74 Bultman Plaza | G28: Petaluma | H28: United States | I28: 94975 | J28: Yes
B29: 50124-88608-EO | C29: Vivie Danneil | D29: vdanneilr@mtv.com | E29: +353 (751) 346-0399 | F29: 5626 Darwin Avenue | G29: Tralee | H29: Ireland | I29: V92 | J29: No
B30: 00888-74814-UZ | C30: Theresita Newbury | D30: tnewburys@usda.gov | E30: +353 (803) 587-0026 | F30: 79526 Bultman Lane | G30: Clonskeagh | H30: Ireland | I30: D04 | J30: No
B31: 14158-30713-OB | C31: Mozelle Calcutt | D31: mcalcuttt@baidu.com | E31: +353 (928) 869-1762 | F31: 4389 Russell Way | G31: Rathwire | H31: Ireland | I31: Y25 | J31: Yes
B32: 51427-89175-QJ | C32: Adrian Swaine | E32: +1 (303) 486-9517 | F32: 95 Straubel Hill | G32: Aurora | H32: United States | I32: 80044 | J32: No
B33: 52082-49024-ON | C33: Ray Leivesley | D33: rleivesleyv@canalblog.com | E33: +1 (212) 535-7791 | F33: 91 Stephen Drive | G33: Jamaica | H33: United States | I33: 11407 | J33: No
B34: 04540-43685-DV | C34: Nelly Basezzi | D34: nbasezziw@webeden.co.uk | E34: +353 (125) 815-7345 | F34: 923 Mallard Junction | G34: Bailieborough | H34: Ireland | I34: C15 | J34: Yes
B35: 39123-12846-YJ | C35: Gallard Gatheral | D35: ggatheralx@123-reg.co.uk | F35: 40 Clemons Place | G35: Grand Forks | H35: United States | I35: 58207 | J35: No
B36: 44981-99666-XB | C36: Una Welberry | D36: uwelberryy@ebay.co.uk | E36: +44 (392) 503-8132 | F36: 40915 Schlimgen Park | G36: Upton | H36: United Kingdom | I36: DN21 | J36: Yes
B37: 24825-51803-CQ | C37: Faber Eilhart | D37: feilhartz@who.int | E37: +1 (304) 510-6095 | F37: 6966 Victoria Street | G37: Charleston | H37: United States | I37: 25362 | J37: No
B38: 77634-13918-GJ | C38: Zorina Ponting | D38: zponting10@altervista.org | E38: +1 (501) 172-1476 | F38: 7118 Holmberg Court | G38: Little Rock | H38: United States | I38: 72204 | J38: No
B39: 13694-25001-LX | C39: Silvio Strase | D39: sstrase11@booking.com | E39: +1 (303) 579-8015 | F39: 5 Forest Lane | G39: Denver | H39: United States | I39: 80291 | J39: No
B40: 08523-01791-TI | C40: Dorie de la Tremoille | D40: dde12@unesco.org | E40: +1 (612) 492-5160 | F40: 0817 Dennis Street | G40: Minneapolis | H40: United States | I40: 55458 | J40: No
...

Sheet TotalSales
A3: Sum of Sales | C3: coffee type
A4: Years | B4: Order Date | C4: Arabica | D4: Excelsa | E4: Liberica | F4: Robusta
A5: 2022 | B5: Jan | D5: 21.87 | E5: 178.71
B6: Feb | C6: 11.94
B7: Mar | E7: 89.355 | F7: 130.14
B8: Apr | E8: 49.695 | F8: 7.17
B9: May | E9: 4.755
B10: Jun | D10: 13.365 | E10: 145.82 | F10: 114.425
B11: Jul | D11: 66.69 | F11: 61.69
B12: Aug | C12: 56.76 | E12: 15.54

Sheet Dashboard

Sheet order_data
A1: Order ID | B1: Order Date | C1: Customer ID | D1: Product ID | E1: Quantity | F1: Customer | G1: Email | H1: Country | I1: coffee type | J1: Roast Type | K1: Size | L1: Unit Price | M1: Sales
A2: QEV-37451-860 | B2: 43713 | C2: 17670-51384-MA | D2: R-M-1 | E2: 2 | F2: =_xlfn.XLOOKUP(C2,customer_data!$B$1:$B$165,customer_data!$C$1:$C$165,,0) -> Aloisia Allner | G2: =IF(_xlfn.XLOOKUP(C2,customer_data!$B$1:$B$165,customer_data!$D$1:$D$165,,0)=0,"",_xlfn.XLOOKUP(C2,customer_data!$B$1:$B$165,customer_data!$D$1:$D$165,,0)) -> aallner0@lulu.com | H2: =_xlfn.XLOOKUP(C2,customer_data!$B$1:$B$165,customer_data!$H$1:$H$165,,0) -> United States | I2: =INDEX(Product_data!$A$1:$G$49,MATCH(order_data!$D2,Product_data!$A$1:$A$49,0),MATCH(order_data!I$1,Product_data!$A$1:$G$1,0)) -> Robusta | J2: =INDEX(Product_data!$A$1:$G$49,MATCH(order_data!$D2,Product_data!$A$1:$A$49,0),MATCH(order_data!J$1,Product_data!$A$1:$G$1,0)) -> Medium Roast | K2: =INDEX(Product_data!$A$1:$G$49,MATCH(order_data!$D2,Product_data!$A$1:$A$49,0),MATCH(order_data!K$1,Product_data!$A$1:$G$1,0)) -> 1 | L2: =INDEX(Product_data!$A$1:$G$49,MATCH(order_data!$D2,Product_data!$A$1:$A$49,0),MATCH(order_data!L$1,Product_data!$A$1:$G$1,0)) -> 9.95 | M2: =L2*E2 -> 19.9
A3: QEV-37451-860 | B3: 43713 | C3: 17670-51384-MA | D3: E-M-0.5 | E3: 5 | F3: =_xlfn.XLOOKUP(C3,customer_data!$B$1:$B$165,customer_data!$C$1:$C$165,,0) -> Aloisia Allner | G3: =IF(_xlfn.XLOOKUP(C3,customer_data!$B$1:$B$165,customer_data!$D$1:$D$165,,0)=0,"",_xlfn.XLOOKUP(C3,customer_data!$B$1:$B$165,customer_data!$D$1:$D$165,,0)) -> aallner0@lulu.com | H3: =_xlfn.XLOOKUP(C3,customer_data!$B$1:$B$165,customer_data!$H$1:$H$165,,0) -> United States | I3: =INDEX(Product_data!$A$1:$G$49,MATCH(order_data!$D3,Product_data!$A$1:$A$49,0),MATCH(order_data!I$1,Product_data!$A$1:$G$1,0)) -> Excelsa | J3: =INDEX(Product_data!$A$1:$G$49,MATCH(order_data!$D3,Product_data!$A$1:$A$49,0),MATCH(order_data!J$1,Product_data!$A$1:$G$1,0)) -> Medium Roast | K3: =INDEX(Product_data!$A$1:$G$49,MATCH(order_data!$D3,Product_data!$A$1:$A$49,0),MATCH(order_data!K$1,Product_data!$A$1:$G$1,0)) -> 0.5 | L3: =INDEX(Product_data!$A$1:$G$49,MATCH(order_data!$D3,Product_data!$A$1:$A$49,0),MATCH(order_data!L$1,Product_data!$A$1:$G$1,0)) -> 8.25 | M3: =L3*E3 -> 41.25
A4: FAA-43335-268 | B4: 44364 | C4: 21125-22134-PX | D4: A-L-1 | E4: 1 | F4: =_xlfn.XLOOKUP(C4,customer_data!$B$1:$B$165,customer_data!$C$1:$C$165,,0) -> Jami Redholes | G4: =IF(_xlfn.XLOOKUP(C4,customer_data!$B$1:$B$165,customer_data!$D$1:$D$165,,0)=0,"",_xlfn.XLOOKUP(C4,customer_data!$B$1:$B$165,customer_data!$D$1:$D$165,,0)) -> jredholes2@tmall.com | H4: =_xlfn.XLOOKUP(C4,customer_data!$B$1:$B$165,customer_data!$H$1:$H$165,,0) -> United States | I4: =INDEX(Product_data!$A$1:$G$49,MATCH(order_data!$D4,Product_data!$A$1:$A$49,0),MATCH(order_data!I$1,Product_data!$A$1:$G$1,0)) -> Arabica | J4: =INDEX(Product_data!$A$1:$G$49,MATCH(order_data!$D4,Product_data!$A$1:$A$49,0),MATCH(order_data!J$1,Product_data!$A$1:$G$1,0)) -> Light Roast | K4: =INDEX(Product_data!$A$1:$G$49,MATCH(order_data!$D4,Product_data!$A$1:$A$49,0),MATCH(order_data!K$1,Product_data!$A$1:$G$1,0)) -> 1 | L4: =INDEX(Product_data!$A$1:$G$49,MATCH(order_data!$D4,Product_data!$A$1:$A$49,0),MATCH(order_data!L$1,Product_data!$A$1:$G$1,0)) -> 12.95 | M4: =L4*E4 -> 12.95
A5: KAC-83089-793 | B5: 44392 | C5: 23806-46781-OU | D5: E-M-1 | E5: 2 | F5: =_xlfn.XLOOKUP(C5,customer_data!$B$1:$B$165,customer_data!$C$1:$C$165,,0) -> Christoffer O' Shea | G5: =IF(_xlfn.XLOOKUP(C5,customer_data!$B$1:$B$165,customer_data!$D$1:$D$165,,0)=0,"",_xlfn.XLOOKUP(C5,customer_data!$B$1:$B$165,customer_data!$D$1:$D$165,,0)) | H5: =_xlfn.XLOOKUP(C5,customer_data!$B$1:$B$165,customer_data!$H$1:$H$165,,0) -> Ireland | I5: =INDEX(Product_data!$A$1:$G$49,MATCH(order_data!$D5,Product_data!$A$1:$A$49,0),MATCH(order_data!I$1,Product_data!$A$1:$G$1,0)) -> Excelsa | J5: =INDEX(Product_data!$A$1:$G$49,MATCH(order_data!$D5,Product_data!$A$1:$A$49,0),MATCH(order_data!J$1,Product_data!$A$1:$G$1,0)) -> Medium Roast | K5: =INDEX(Product_data!$A$1:$G$49,MATCH(order_data!$D5,Product_data!$A$1:$A$49,0),MATCH(order_data!K$1,Product_data!$A$1:$G$1,0)) -> 1 | L5: =INDEX(Product_data!$A$1:$G$49,MATCH(order_data!$D5,Product_data!$A$1:$A$49,0),MATCH(order_data!L$1,Product_data!$A$1:$G$1,0)) -> 13.75 | M5: =L5*E5 -> 27.5
A6: KAC-83089-793 | B6: 44392 | C6: 23806-46781-OU | D6: R-L-2.5 | E6: 2 | F6: =_xlfn.XLOOKUP(C6,customer_data!$B$1:$B$165,customer_data!$C$1:$C$165,,0) -> Christoffer O' Shea | G6: =IF(_xlfn.XLOOKUP(C6,customer_data!$B$1:$B$165,customer_data!$D$1:$D$165,,0)=0,"",_xlfn.XLOOKUP(C6,customer_data!$B$1:$B$165,customer_data!$D$1:$D$165,,0)) | H6: =_xlfn.XLOOKUP(C6,customer_data!$B$1:$B$165,customer_data!$H$1:$H$165,,0) -> Ireland | I6: =INDEX(Product_data!$A$1:$G$49,MATCH(order_data!$D6,Product_data!$A$1:$A$49,0),MATCH(order_data!I$1,Product_data!$A$1:$G$1,0)) -> Robusta | J6: =INDEX(Product_data!$A$1:$G$49,MATCH(order_data!$D6,Product_data!$A$1:$A$49,0),MATCH(order_data!J$1,Product_data!$A$1:$G$1,0)) -> Light Roast | K6: =INDEX(Product_data!$A$1:$G$49,MATCH(order_data!$D6,Product_data!$A$1:$A$49,0),MATCH(order_data!K$1,Product_data!$A$1:$G$1,0)) -> 2.5 | L6: =INDEX(Product_data!$A$1:$G$49,MATCH(order_data!$D6,Product_data!$A$1:$A$49,0),MATCH(order_data!L$1,Product_data!$A$1:$G$1,0)) -> 27.485 | M6: =L6*E6 -> 54.97
A7: CVP-18956-553 | B7: 44412 | C7: 86561-91660-RB | D7: L-D-1 | E7: 3 | F7: =_xlfn.XLOOKUP(C7,customer_data!$B$1:$B$165,customer_data!$C$1:$C$165,,0) -> Beryle Cottier | G7: =IF(_xlfn.XLOOKUP(C7,customer_data!$B$1:$B$165,customer_data!$D$1:$D$165,,0)=0,"",_xlfn.XLOOKUP(C7,customer_data!$B$1:$B$165,customer_data!$D$1:$D$165,,0)) | H7: =_xlfn.XLOOKUP(C7,customer_data!$B$1:$B$165,customer_data!$H$1:$H$165,,0) -> United States | I7: =INDEX(Product_data!$A$1:$G$49,MATCH(order_data!$D7,Product_data!$A$1:$A$49,0),MATCH(order_data!I$1,Product_data!$A$1:$G$1,0)) -> Liberica | J7: =INDEX(Product_data!$A$1:$G$49,MATCH(order_data!$D7,Product_data!$A$1:$A$49,0),MATCH(order_data!J$1,Product_data!$A$1:$G$1,0)) -> Dark Roast | K7: =INDEX(Product_data!$A$1:$G$49,MATCH(order_data!$D7,Product_data!$A$1:$A$49,0),MATCH(order_data!K$1,Product_data!$A$1:$G$1,0)) -> 1 | L7: =INDEX(Product_data!$A$1:$G$49,MATCH(order_data!$D7,Product_data!$A$1:$A$49,0),MATCH(order_data!L$1,Product_data!$A$1:$G$1,0)) -> 12.95 | M7: =L7*E7 -> 38.85
A8: IPP-31994-879 | B8: 44582 | C8: 65223-29612-CB | D8: E-D-0.5 | E8: 3 | F8: =_xlfn.XLOOKUP(C8,customer_data!$B$1:$B$165,customer_data!$C$1:$C$165,,0) -> Shaylynn Lobe | G8: =IF(_xlfn.XLOOKUP(C8,customer_data!$B$1:$B$165,customer_data!$D$1:$D$165,,0)=0,"",_xlfn.XLOOKUP(C8,customer_data!$B$1:$B$165,customer_data!$D$1:$D$165,,0)) -> slobe6@nifty.com | H8: =_xlfn.XLOOKUP(C8,customer_data!$B$1:$B$165,customer_data!$H$1:$H$165,,0) -> United States | I8: =INDEX(Product_data!$A$1:$G$49,MATCH(order_data!$D8,Product_data!$A$1:$A$49,0),MATCH(order_data!I$1,Product_data!$A$1:$G$1,0)) -> Excelsa | J8: =INDEX(Product_data!$A$1:$G$49,MATCH(order_data!$D8,Product_data!$A$1:$A$49,0),MATCH(order_data!J$1,Product_data!$A$1:$G$1,0)) -> Dark Roast | K8: =INDEX(Product_data!$A$1:$G$49,MATCH(order_data!$D8,Product_data!$A$1:$A$49,0),MATCH(order_data!K$1,Product_data!$A$1:$G$1,0)) -> 0.5 | L8: =INDEX(Product_data!$A$1:$G$49,MATCH(order_data!$D8,Product_data!$A$1:$A$49,0),MATCH(order_data!L$1,Product_data!$A$1:$G$1,0)) -> 7.29 | M8: =L8*E8 -> 21.87
A9: SNZ-65340-705 | B9: 44701 | C9: 21134-81676-FR | D9: L-L-0.2 | E9: 1 | F9: =_xlfn.XLOOKUP(C9,customer_data!$B$1:$B$165,customer_data!$C$1:$C$165,,0) -> Melvin Wharfe | G9: =IF(_xlfn.XLOOKUP(C9,customer_data!$B$1:$B$165,customer_data!$D$1:$D$165,,0)=0,"",_xlfn.XLOOKUP(C9,customer_data!$B$1:$B$165,customer_data!$D$1:$D$165,,0)) | H9: =_xlfn.XLOOKUP(C9,customer_data!$B$1:$B$165,customer_data!$H$1:$H$165,,0) -> Ireland | I9: =INDEX(Product_data!$A$1:$G$49,MATCH(order_data!$D9,Product_data!$A$1:$A$49,0),MATCH(order_data!I$1,Product_data!$A$1:$G$1,0)) -> Liberica | J9: =INDEX(Product_data!$A$1:$G$49,MATCH(order_data!$D9,Product_data!$A$1:$A$49,0),MATCH(order_data!J$1,Product_data!$A$1:$G$1,0)) -> Light Roast | K9: =INDEX(Product_data!$A$1:$G$49,MATCH(order_data!$D9,Product_data!$A$1:$A$49,0),MATCH(order_data!K$1,Product_data!$A$1:$G$1,0)) -> 0.2 | L9: =INDEX(Product_data!$A$1:$G$49,MATCH(order_data!$D9,Product_data!$A$1:$A$49,0),MATCH(order_data!L$1,Product_data!$A$1:$G$1,0)) -> 4.755 | M9: =L9*E9 -> 4.755
A10: EZT-46571-659 | B10: 43467 | C10: 03396-68805-ZC | D10: R-M-0.5 | E10: 3 | F10: =_xlfn.XLOOKUP(C10,customer_data!$B$1:$B$165,customer_data!$C$1:$C$165,,0) -> Guthrey Petracci | G10: =IF(_xlfn.XLOOKUP(C10,customer_data!$B$1:$B$165,customer_data!$D$1:$D$165,,0)=0,"",_xlfn.XLOOKUP(C10,customer_data!$B$1:$B$165,customer_data!$D$1:$D$165,,0)) -> gpetracci8@livejournal.com | H10: =_xlfn.XLOOKUP(C10,customer_data!$B$1:$B$165,customer_data!$H$1:$H$165,,0) -> United States | I10: =INDEX(Product_data!$A$1:$G$49,MATCH(order_data!$D10,Product_data!$A$1:$A$49,0),MATCH(order_data!I$1,Product_data!$A$1:$G$1,0)) -> Robusta | J10: =INDEX(Product_data!$A$1:$G$49,MATCH(order_data!$D10,Product_data!$A$1:$A$49,0),MATCH(order_data!J$1,Product_data!$A$1:$G$1,0)) -> Medium Roast | K10: =INDEX(Product_data!$A$1:$G$49,MATCH(order_data!$D10,Product_data!$A$1:$A$49,0),MATCH(order_data!K$1,Product_data!$A$1:$G$1,0)) -> 0.5 | L10: =INDEX(Product_data!$A$1:$G$49,MATCH(order_data!$D10,Product_data!$A$1:$A$49,0),MATCH(order_data!L$1,Product_data!$A$1:$G$1,0)) -> 5.97 | M10: =L10*E10 -> 17.91
A11: NWQ-70061-912 | B11: 43713 | C11: 61021-27840-ZN | D11: R-M-0.5 | E11: 1 | F11: =_xlfn.XLOOKUP(C11,customer_data!$B$1:$B$165,customer_data!$C$1:$C$165,,0) -> Rodger Raven | G11: =IF(_xlfn.XLOOKUP(C11,customer_data!$B$1:$B$165,customer_data!$D$1:$D$165,,0)=0,"",_xlfn.XLOOKUP(C11,customer_data!$B$1:$B$165,customer_data!$D$1:$D$165,,0)) -> rraven9@ed.gov | H11: =_xlfn.XLOOKUP(C11,customer_data!$B$1:$B$165,customer_data!$H$1:$H$165,,0) -> United States | I11: =INDEX(Product_data!$A$1:$G$49,MATCH(order_data!$D11,Product_data!$A$1:$A$49,0),MATCH(order_data!I$1,Product_data!$A$1:$G$1,0)) -> Robusta | J11: =INDEX(Product_data!$A$1:$G$49,MATCH(order_data!$D11,Product_data!$A$1:$A$49,0),MATCH(order_data!J$1,Product_data!$A$1:$G$1,0)) -> Medium Roast | K11: =INDEX(Product_data!$A$1:$G$49,MATCH(order_data!$D11,Product_data!$A$1:$A$49,0),MATCH(order_data!K$1,Product_data!$A$1:$G$1,0)) -> 0.5 | L11: =INDEX(Product_data!$A$1:$G$49,MATCH(order_data!$D11,Product_data!$A$1:$A$49,0),MATCH(order_data!L$1,Product_data!$A$1:$G$1,0)) -> 5.97 | M11: =L11*E11 -> 5.97
A12: BKK-47233-845 | B12: 44263 | C12: 76239-90137-UQ | D12: A-D-1 | E12: 4 | F12: =_xlfn.XLOOKUP(C12,customer_data!$B$1:$B$165,customer_data!$C$1:$C$165,,0) -> Ferrell Ferber | G12: =IF(_xlfn.XLOOKUP(C12,customer_data!$B$1:$B$165,customer_data!$D$1:$D$165,,0)=0,"",_xlfn.XLOOKUP(C12,customer_data!$B$1:$B$165,customer_data!$D$1:$D$165,,0)) -> fferbera@businesswire.com | H12: =_xlfn.XLOOKUP(C12,customer_data!$B$1:$B$165,customer_data!$H$1:$H$165,,0) -> United States | I12: =INDEX(Product_data!$A$1:$G$49,MATCH(order_data!$D12,Product_data!$A$1:$A$49,0),MATCH(order_data!I$1,Product_data!$A$1:$G$1,0)) -> Arabica | J12: =INDEX(Product_data!$A$1:$G$49,MATCH(order_data!$D12,Product_data!$A$1:$A$49,0),MATCH(order_data!J$1,Product_data!$A$1:$G$1,0)) -> Dark Roast | K12: =INDEX(Product_data!$A$1:$G$49,MATCH(order_data!$D12,Product_data!$A$1:$A$49,0),MATCH(order_data!K$1,Product_data!$A$1:$G$1,0)) -> 1 | L12: =INDEX(Product_data!$A$1:$G$49,MATCH(order_data!$D12,Product_data!$A$1:$A$49,0),MATCH(order_data!L$1,Product_data!$A$1:$G$1,0)) -> 9.95 | M12: =L12*E12 -> 39.8
A13: VQR-01002-970 | B13: 44132 | C13: 49315-21985-BB | D13: E-L-2.5 | E13: 5 | F13: =_xlfn.XLOOKUP(C13,customer_data!$B$1:$B$165,customer_data!$C$1:$C$165,,0) -> Duky Phizackerly | G13: =IF(_xlfn.XLOOKUP(C13,customer_data!$B$1:$B$165,customer_data!$D$1:$D$165,,0)=0,"",_xlfn.XLOOKUP(C13,customer_data!$B$1:$B$165,customer_data!$D$1:$D$165,,0)) -> dphizackerlyb@utexas.edu | H13: =_xlfn.XLOOKUP(C13,customer_data!$B$1:$B$165,customer_data!$H$1:$H$165,,0) -> United States | I13: =INDEX(Product_data!$A$1:$G$49,MATCH(order_data!$D13,Product_data!$A$1:$A$49,0),MATCH(order_data!I$1,Product_data!$A$1:$G$1,0)) -> Excelsa | J13: =INDEX(Product_data!$A$1:$G$49,MATCH(order_data!$D13,Product_data!$A$1:$A$49,0),MATCH(order_data!J$1,Product_data!$A$1:$G$1,0)) -> Light Roast | K13: =INDEX(Product_data!$A$1:$G$49,MATCH(order_data!$D13,Product_data!$A$1:$A$49,0),MATCH(order_data!K$1,Product_data!$A$1:$G$1,0)) -> 2.5 | L13: =INDEX(Product_data!$A$1:$G$49,MATCH(order_data!$D13,Product_data!$A$1:$A$49,0),MATCH(order_data!L$1,Product_data!$A$1:$G$1,0)) -> 34.155 | M13: =L13*E13 -> 170.775
... A130: OIL-26493-755 | B130: 44439 | C130: 19017-95853-EK | D130: A-M-0.5 | E130: 1 | F130: =_xlfn.XLOOKUP(C130,customer_data!$B$1:$B$165,customer_data!$C$1:$C$165,,0) -> Timofei Woofinden | G130: =IF(_xlfn.XLOOKUP(C130,customer_data!$B$1:$B$165,customer_data!$D$1:$D$165,,0)=0,"",_xlfn.XLOOKUP(C130,customer_data!$B$1:$B$165,customer_data!$D$1:$D$165,,0)) -> twoofinden3k@businesswire.com | H130: =_xlfn.XLOOKUP(C130,customer_data!$B$1:$B$165,customer_data!$H$1:$H$165,,0) -> United States | I130: =INDEX(Product_data!$A$1:$G$49,MATCH(order_data!$D130,Product_data!$A$1:$A$49,0),MATCH(order_data!I$1,Product_data!$A$1:$G$1,0)) -> Arabica | J130: =INDEX(Product_data!$A$1:$G$49,MATCH(order_data!$D130,Product_data!$A$1:$A$49,0),MATCH(order_data!J$1,Product_data!$A$1:$G$1,0)) -> Medium Roast | K130: =INDEX(Product_data!$A$1:$G$49,MATCH(order_data!$D130,Product_data!$A$1:$A$49,0),MATCH(order_data!K$1,Product_data!$A$1:$G$1,0)) -> 0.5 | L130: =INDEX(Product_data!$A$1:$G$49,MATCH(order_data!$D130,Product_data!$A$1:$A$49,0),MATCH(order_data!L$1,Product_data!$A$1:$G$1,0)) -> 6.75 | M130: =L130*E130 -> 6.75

Sheet Product_data
A1: Product ID | B1: Coffee Type | C1: Roast Type | D1: Size | E1: Unit Price | F1: Price per 100g | G1: Profit
A2: A-L-0.2 | B2: Arabica | C2: Light Roast | D2: 0.2 | E2: 3.885 | F2: 1.9425 | G2: 0.34965
A3: A-L-0.5 | B3: Arabica | C3: Light Roast | D3: 0.5 | E3: 7.77 | F3: 1.554 | G3: 0.6993
A4: A-L-1 | B4: Arabica | C4: Light Roast | D4: 1 | E4: 12.95 | F4: 1.295 | G4: 1.1655
A5: A-L-2.5 | B5: Arabica | C5: Light Roast | D5: 2.5 | E5: 29.785 | F5: 1.1914 | G5: 2.68065
A6: A-M-0.2 | B6: Arabica | C6: Medium Roast | D6: 0.2 | E6: 3.375 | F6: 1.6875 | G6: 0.30375
A7: A-M-0.5 | B7: Arabica | C7: Medium Roast | D7: 0.5 | E7: 6.75 | F7: 1.35 | G7: 0.6075
A8: A-M-1 | B8: Arabica | C8: Medium Roast | D8: 1 | E8: 11.25 | F8: 1.125 | G8: 1.0125
A9: A-M-2.5 | B9: Arabica | C9: Medium Roast | D9: 2.5 | E9: 25.875 | F9: 1.035 | G9: 2.32875
A10: A-D-0.2 | B10: Arabica | C10: Dark Roast | D10: 0.2 | E10: 2.985 | F10: 1.4925 | G10: 0.26865
A11: A-D-0.5 | B11: Arabica | C11: Dark Roast | D11: 0.5 | E11: 5.97 | F11: 1.194 | G11: 0.5373
A12: A-D-1 | B12: Arabica | C12: Dark Roast | D12: 1 | E12: 9.95 | F12: 0.995 | G12: 0.8955
A13: A-D-2.5 | B13: Arabica | C13: Dark Roast | D13: 2.5 | E13: 22.885 | F13: 0.9154 | G13: 2.05965
... A49: E-D-2.5 | B49: Excelsa | C49: Dark Roast | D49: 2.5 | E49: 27.945 | F49: 1.1178 | G49: 3.07395
